inputs/input5.txt
2024-11-18-10-10-15 47 Emre AAPL Buy 11 40.6
2024-11-18-10-10-15 32 Ali MSFT Sell 13 39.7
2024-11-18-10-10-15 44 Oğuz NVDA Buy 8 39.7
2024-11-18-10-10-30 44 Oğuz MSFT Sell 11 34.4
2024-11-18-10-10-45 44 Oğuz MSFT Sell 6 38.7
2024-11-18-10-10-45 34 Mustafa MSFT Sell 12 36.5
2024-11-18-10-11-15 47 Emre MSFT Buy 13 37.4
2024-11-18-10-11-15 47 Emre MRT Sell 14 44.5
2024-11-18-10-11-15 32 Ali NVDA Buy 5 43.8
2024-11-18-10-11-30 34 Mustafa AAPL Buy 9 40.6
2024-11-18-10-11-45 44 Oğuz MSFT Sell 15 32.1
2024-11-18-10-11-45 47 Emre BAC Buy 16 39.0
2024-11-18-10-12-15 32 Ali MRT Buy 6 35.7
2024-11-18-10-12-15 34 Mustafa NVDA Buy 8 30.9
2024-11-18-10-12-15 47 Emre MSFT Sell 19 32.3
2024-11-18-10-12-30 34 Mustafa BAC Buy 20 32.1
2024-11-18-10-12-45 44 Oğuz MSFT Sell 7 33.4
2024-11-18-10-12-45 47 Emre MRT Buy 10 38.9
2024-11-18-10-13-15 34 Mustafa AAPL Sell 7 34.0
2024-11-18-10-13-15 47 Emre NVDA Buy 14 43.6
2024-11-18-10-13-15 47 Emre AAPL Buy 11 30.3
2024-11-18-10-13-30 34 Mustafa NVDA Buy 9 36.0
2024-11-18-10-13-45 32 Ali MSFT Sell 11 36.2
2024-11-18-10-13-45 44 Oğuz NVDA Buy 14 32.5
2024-11-18-10-14-15 47 Emre MRT Buy 9 31.0
2024-11-18-10-14-15 44 Oğuz MRT Sell 13 37.6
2024-11-18-10-14-15 34 Mustafa AAPL Buy 7 39.2
2024-11-18-10-14-30 44 Oğuz NVDA Sell 19 34.4
2024-11-18-10-14-45 32 Ali BAC Sell 5 31.3
2024-11-18-10-14-45 47 Emre BAC Sell 14 42.1
2024-11-18-10-15-15 32 Ali BAC Buy 5 40.8
2024-11-18-10-15-15 32 Ali AAPL Sell 9 37.0
2024-11-18-10-15-15 32 Ali AAPL Buy 12 37.2
2024-11-18-10-15-30 44 Oğuz AAPL Sell 13 32.1
2024-11-18-10-15-45 47 Emre AAPL Sell 20 36.9
2024-11-18-10-15-45 32 Ali AAPL Sell 8 32.2
2024-11-18-10-16-15 47 Emre AAPL Buy 8 39.0
2024-11-18-10-16-15 32 Ali MRT Sell 5 31.1
2024-11-18-10-16-15 47 Emre MRT Sell 20 35.0
2024-11-18-10-16-30 32 Ali NVDA Sell 16 32.5
2024-11-18-10-16-45 47 Emre MSFT Sell 12 36.4
2024-11-18-10-16-45 44 Oğuz NVDA Buy 16 33.2
2024-11-18-10-17-15 34 Mustafa AAPL Sell 12 33.1
2024-11-18-10-17-15 44 Oğuz AAPL Buy 9 39.2
2024-11-18-10-17-15 32 Ali NVDA Buy 18 39.8
2024-11-18-10-17-30 47 Emre BAC Sell 11 43.7
2024-11-18-10-17-45 47 Emre MRT Buy 15 35.1
2024-11-18-10-17-45 44 Oğuz BAC Sell 5 38.2
2024-11-18-10-18-15 34 Mustafa BAC Sell 6 31.3
2024-11-18-10-18-15 44 Oğuz AAPL Buy 16 35.6
2024-11-18-10-18-15 47 Emre NVDA Buy 16 34.5
2024-11-18-10-18-30 47 Emre BAC Buy 16 38.0
2024-11-18-10-18-45 47 Emre NVDA Sell 17 39.5
2024-11-18-10-18-45 47 Emre AAPL Buy 11 40.3
2024-11-18-10-19-15 44 Oğuz NVDA Buy 12 35.3
2024-11-18-10-19-15 34 Mustafa MSFT Sell 17 32.8
2024-11-18-10-19-15 47 Emre AAPL Buy 11 32.4
2024-11-18-10-19-30 34 Mustafa MRT Sell 6 33.1
2024-11-18-10-19-45 47 Emre MSFT Sell 6 40.8
2024-11-18-10-19-45 47 Emre BAC Sell 14 43.9
2024-11-18-10-20-15 34 Mustafa AAPL Buy 12 36.6
2024-11-18-10-20-15 47 Emre BAC Buy 11 40.1
2024-11-18-10-20-15 44 Oğuz BAC Sell 14 33.6
2024-11-18-10-20-30 47 Emre AAPL Sell 15 38.2
2024-11-18-10-20-45 44 Oğuz NVDA Buy 19 34.4
2024-11-18-10-20-45 34 Mustafa BAC Buy 10 38.5
2024-11-18-10-21-15 44 Oğuz MSFT Sell 14 40.9
2024-11-18-10-21-15 32 Ali NVDA Buy 20 38.4
2024-11-18-10-21-15 34 Mustafa NVDA Sell 18 41.8
2024-11-18-10-21-30 44 Oğuz AAPL Sell 7 39.0
2024-11-18-10-21-45 32 Ali MSFT Sell 11 30.1
2024-11-18-10-21-45 44 Oğuz BAC Sell 8 41.8
2024-11-18-10-22-15 34 Mustafa BAC Sell 7 45.0
2024-11-18-10-22-15 47 Emre AAPL Sell 10 41.2
2024-11-18-10-22-15 34 Mustafa AAPL Sell 20 41.2
2024-11-18-10-22-30 32 Ali BAC Buy 9 38.3
2024-11-18-10-22-45 34 Mustafa AAPL Sell 12 36.7
2024-11-18-10-22-45 44 Oğuz MSFT Sell 11 38.1
2024-11-18-10-23-15 47 Emre NVDA Sell 17 34.5
2024-11-18-10-23-15 34 Mustafa NVDA Sell 18 37.3
2024-11-18-10-23-15 34 Mustafa MRT Buy 8 35.4
2024-11-18-10-23-30 44 Oğuz NVDA Sell 14 39.8
2024-11-18-10-23-45 34 Mustafa NVDA Buy 20 30.4
2024-11-18-10-23-45 34 Mustafa BAC Sell 5 39.2
2024-11-18-10-24-15 32 Ali MRT Buy 20 41.4
2024-11-18-10-24-15 44 Oğuz MRT Sell 9 35.9
2024-11-18-10-24-15 34 Mustafa MSFT Buy 8 33.9
2024-11-18-10-24-30 44 Oğuz MRT Buy 18 35.8
2024-11-18-10-24-45 32 Ali MRT Sell 20 43.0
2024-11-18-10-24-45 32 Ali BAC Buy 19 39.3
2024-11-18-10-25-15 44 Oğuz MRT Buy 16 44.1
2024-11-18-10-25-15 34 Mustafa AAPL Sell 20 42.0
2024-11-18-10-25-15 44 Oğuz BAC Sell 16 41.2
2024-11-18-10-25-30 44 Oğuz AAPL Sell 11 32.0
2024-11-18-10-25-45 44 Oğuz MSFT Buy 18 43.1
2024-11-18-10-25-45 47 Emre BAC Sell 19 35.7
2024-11-18-10-26-15 32 Ali BAC Buy 10 41.8
2024-11-18-10-26-15 34 Mustafa MRT Sell 16 36.3
2024-11-18-10-26-15 34 Mustafa NVDA Buy 5 38.7
2024-11-18-10-26-30 44 Oğuz AAPL Buy 5 32.6
2024-11-18-10-26-45 47 Emre MRT Buy 20 43.5
2024-11-18-10-26-45 47 Emre BAC Buy 9 33.0
2024-11-18-10-27-15 47 Emre BAC Sell 17 32.2
2024-11-18-10-27-15 32 Ali AAPL Buy 7 37.4
2024-11-18-10-27-15 32 Ali MRT Sell 17 36.6
2024-11-18-10-27-30 34 Mustafa AAPL Sell 12 41.4
2024-11-18-10-27-45 34 Mustafa AAPL Sell 16 42.8
2024-11-18-10-27-45 44 Oğuz BAC Sell 12 32.9
2024-11-18-10-28-15 32 Ali NVDA Buy 18 36.0
2024-11-18-10-28-15 47 Emre AAPL Sell 11 38.9
2024-11-18-10-28-15 32 Ali AAPL Buy 10 43.8
2024-11-18-10-28-30 44 Oğuz BAC Buy 5 34.7
2024-11-18-10-28-45 44 Oğuz MSFT Buy 14 42.3
2024-11-18-10-28-45 47 Emre MRT Sell 16 32.3
2024-11-18-10-29-15 32 Ali BAC Sell 12 39.0
2024-11-18-10-29-15 47 Emre MRT Buy 19 36.9
2024-11-18-10-29-15 32 Ali AAPL Sell 5 33.2
2024-11-18-10-29-30 47 Emre MRT Buy 12 37.6
2024-11-18-10-29-45 32 Ali BAC Sell 17 43.2
2024-11-18-10-29-45 34 Mustafa MRT Sell 11 37.8
2024-11-18-10-30-15 34 Mustafa NVDA Sell 13 43.2
2024-11-18-10-30-15 32 Ali BAC Sell 18 37.6
2024-11-18-10-30-15 34 Mustafa BAC Buy 9 36.5
2024-11-18-10-30-30 47 Emre MRT Buy 9 42.5
2024-11-18-10-30-45 44 Oğuz AAPL Sell 20 44.4
2024-11-18-10-30-45 47 Emre BAC Buy 7 32.8
2024-11-18-10-31-15 32 Ali NVDA Buy 16 32.2
2024-11-18-10-31-15 32 Ali BAC Buy 6 44.7
2024-11-18-10-31-15 34 Mustafa NVDA Sell 20 35.2
2024-11-18-10-31-30 47 Emre MSFT Buy 6 43.9
2024-11-18-10-31-45 44 Oğuz MRT Sell 10 32.0
2024-11-18-10-31-45 34 Mustafa NVDA Sell 20 38.2
2024-11-18-10-32-15 34 Mustafa MSFT Buy 10 41.7
2024-11-18-10-32-15 44 Oğuz MSFT Sell 13 40.3
2024-11-18-10-32-15 34 Mustafa MSFT Buy 5 36.1
2024-11-18-10-32-30 44 Oğuz MRT Sell 13 37.6
2024-11-18-10-32-45 44 Oğuz MSFT Sell 19 33.7
2024-11-18-10-32-45 44 Oğuz MRT Sell 5 40.5
2024-11-18-10-33-15 34 Mustafa MRT Buy 17 42.0
2024-11-18-10-33-15 44 Oğuz BAC Buy 12 31.1
2024-11-18-10-33-15 32 Ali MSFT Buy 8 34.1
2024-11-18-10-33-30 47 Emre MSFT Buy 6 34.9
2024-11-18-10-33-45 44 Oğuz MSFT Sell 14 33.4
2024-11-18-10-33-45 32 Ali AAPL Buy 7 35.5
2024-11-18-10-34-15 47 Emre MRT Sell 7 43.0
2024-11-18-10-34-15 32 Ali MSFT Buy 11 38.7
2024-11-18-10-34-15 44 Oğuz MSFT Sell 9 41.8
2024-11-18-10-34-30 34 Mustafa MSFT Sell 11 36.6
2024-11-18-10-34-45 32 Ali MSFT Sell 16 34.6
2024-11-18-10-34-45 47 Emre BAC Buy 15 36.9
2024-11-18-10-35-15 34 Mustafa MRT Buy 9 36.8
2024-11-18-10-35-15 47 Emre NVDA Buy 17 37.5
2024-11-18-10-35-15 34 Mustafa MSFT Buy 16 41.1
2024-11-18-10-35-30 34 Mustafa MRT Sell 5 43.9
2024-11-18-10-35-45 32 Ali BAC Sell 12 44.5
2024-11-18-10-35-45 34 Mustafa NVDA Sell 10 33.5
2024-11-18-10-36-15 34 Mustafa NVDA Buy 5 35.2
2024-11-18-10-36-15 34 Mustafa AAPL Sell 8 39.4
2024-11-18-10-36-15 34 Mustafa BAC Sell 18 34.5
2024-11-18-10-36-30 47 Emre NVDA Sell 18 36.1
2024-11-18-10-36-45 32 Ali NVDA Sell 19 30.1
2024-11-18-10-36-45 34 Mustafa MRT Sell 15 36.3
2024-11-18-10-37-15 32 Ali MSFT Buy 18 30.1
2024-11-18-10-37-15 32 Ali NVDA Sell 7 37.2
2024-11-18-10-37-15 32 Ali MSFT Sell 17 37.5
2024-11-18-10-37-30 34 Mustafa MSFT Buy 10 33.4
2024-11-18-10-37-45 47 Emre AAPL Sell 16 36.5
2024-11-18-10-37-45 47 Emre MRT Buy 20 31.8
2024-11-18-10-38-15 47 Emre BAC Buy 7 34.2
2024-11-18-10-38-15 34 Mustafa MRT Sell 20 43.4
2024-11-18-10-38-15 34 Mustafa MRT Buy 18 40.6
2024-11-18-10-38-30 34 Mustafa MRT Buy 20 31.1
2024-11-18-10-38-45 32 Ali NVDA Sell 8 41.1
2024-11-18-10-38-45 32 Ali NVDA Buy 5 34.8
2024-11-18-10-39-15 44 Oğuz BAC Sell 11 37.4
2024-11-18-10-39-15 44 Oğuz MSFT Buy 8 37.2
2024-11-18-10-39-15 32 Ali MSFT Buy 12 39.0
