outputs/output5.txt
Emre bought 11 MSFT for 34.4 USD from Oğuz on 2024-11-18 at 10:11:15
Emre bought 2 MSFT for 36.5 USD from Mustafa on 2024-11-18 at 10:11:15
Emre bought 7 AAPL for 34.0 USD from Mustafa on 2024-11-18 at 10:13:15
Emre bought 10 MRT for 37.6 USD from Oğuz on 2024-11-18 at 10:14:15
Ali bought 5 NVDA for 34.4 USD from Oğuz on 2024-11-18 at 10:14:30
Emre bought 14 NVDA for 34.4 USD from Oğuz on 2024-11-18 at 10:14:30
Emre bought 5 BAC for 31.3 USD from Ali on 2024-11-18 at 10:14:45
Emre bought 4 AAPL for 37.0 USD from Ali on 2024-11-18 at 10:15:15
Mustafa bought 5 AAPL for 37.0 USD from Ali on 2024-11-18 at 10:15:15
Mustafa bought 4 AAPL for 32.1 USD from Oğuz on 2024-11-18 at 10:15:30
Mustafa bought 7 AAPL for 32.1 USD from Oğuz on 2024-11-18 at 10:15:30
Ali bought 2 AAPL for 32.1 USD from Oğuz on 2024-11-18 at 10:15:30
Ali bought 10 AAPL for 36.9 USD from Emre on 2024-11-18 at 10:15:45
Ali bought 6 MRT for 35.0 USD from Emre on 2024-11-18 at 10:16:15
Emre bought 8 AAPL for 32.2 USD from Ali on 2024-11-18 at 10:16:15
Oğuz bought 8 NVDA for 32.5 USD from Ali on 2024-11-18 at 10:16:30
Mustafa bought 8 NVDA for 32.5 USD from Ali on 2024-11-18 at 10:16:30
Oğuz bought 9 AAPL for 36.9 USD from Emre on 2024-11-18 at 10:17:15
Emre bought 5 BAC for 38.2 USD from Oğuz on 2024-11-18 at 10:17:45
Emre bought 5 MRT for 31.1 USD from Ali on 2024-11-18 at 10:17:45
Emre bought 6 BAC for 31.3 USD from Mustafa on 2024-11-18 at 10:18:15
Oğuz bought 12 AAPL for 33.1 USD from Mustafa on 2024-11-18 at 10:18:15
Ali bought 17 NVDA for 39.5 USD from Emre on 2024-11-18 at 10:18:45
Emre bought 6 MRT for 33.1 USD from Mustafa on 2024-11-18 at 10:19:30
Ali bought 5 BAC for 33.6 USD from Oğuz on 2024-11-18 at 10:20:15
Emre bought 9 BAC for 33.6 USD from Oğuz on 2024-11-18 at 10:20:15
Emre bought 7 AAPL for 39.0 USD from Oğuz on 2024-11-18 at 10:21:30
Emre bought 4 AAPL for 36.7 USD from Mustafa on 2024-11-18 at 10:22:45
Mustafa bought 1 NVDA for 34.5 USD from Emre on 2024-11-18 at 10:23:15
Mustafa bought 8 MRT for 35.0 USD from Emre on 2024-11-18 at 10:23:15
Ali bought 1 NVDA for 34.5 USD from Emre on 2024-11-18 at 10:23:15
Oğuz bought 12 NVDA for 34.5 USD from Emre on 2024-11-18 at 10:23:15
Ali bought 3 NVDA for 34.5 USD from Emre on 2024-11-18 at 10:23:15
Ali bought 17 NVDA for 37.3 USD from Mustafa on 2024-11-18 at 10:23:15
Emre bought 5 BAC for 39.2 USD from Mustafa on 2024-11-18 at 10:23:45
Mustafa bought 8 MSFT for 32.1 USD from Oğuz on 2024-11-18 at 10:24:15
Ali bought 3 MRT for 37.6 USD from Oğuz on 2024-11-18 at 10:24:15
Ali bought 6 MRT for 35.0 USD from Emre on 2024-11-18 at 10:24:15
Ali bought 9 MRT for 35.9 USD from Oğuz on 2024-11-18 at 10:24:15
Oğuz bought 16 MRT for 43.0 USD from Ali on 2024-11-18 at 10:25:15
Emre bought 11 AAPL for 32.0 USD from Oğuz on 2024-11-18 at 10:25:30
Oğuz bought 13 MSFT for 39.7 USD from Ali on 2024-11-18 at 10:25:45
Oğuz bought 5 MSFT for 36.5 USD from Mustafa on 2024-11-18 at 10:25:45
Mustafa bought 10 BAC for 35.7 USD from Emre on 2024-11-18 at 10:25:45
Ali bought 9 BAC for 35.7 USD from Emre on 2024-11-18 at 10:25:45
Ali bought 8 BAC for 41.8 USD from Oğuz on 2024-11-18 at 10:26:15
Ali bought 2 MRT for 36.3 USD from Mustafa on 2024-11-18 at 10:26:15
Ali bought 2 BAC for 41.2 USD from Oğuz on 2024-11-18 at 10:26:15
Emre bought 4 MRT for 43.0 USD from Ali on 2024-11-18 at 10:26:45
Emre bought 14 MRT for 36.3 USD from Mustafa on 2024-11-18 at 10:26:45
Ali bought 1 AAPL for 36.9 USD from Emre on 2024-11-18 at 10:27:15
Ali bought 6 AAPL for 36.7 USD from Mustafa on 2024-11-18 at 10:27:15
Ali bought 17 BAC for 32.2 USD from Emre on 2024-11-18 at 10:27:15
Emre bought 2 MRT for 36.6 USD from Ali on 2024-11-18 at 10:27:15
Emre bought 7 BAC for 32.9 USD from Oğuz on 2024-11-18 at 10:27:45
Emre bought 5 BAC for 32.9 USD from Oğuz on 2024-11-18 at 10:27:45
Ali bought 10 AAPL for 38.2 USD from Emre on 2024-11-18 at 10:28:15
Oğuz bought 5 MSFT for 36.5 USD from Mustafa on 2024-11-18 at 10:28:45
Oğuz bought 9 MSFT for 32.3 USD from Emre on 2024-11-18 at 10:28:45
Oğuz bought 16 MRT for 32.3 USD from Emre on 2024-11-18 at 10:28:45
Oğuz bought 4 AAPL for 33.2 USD from Ali on 2024-11-18 at 10:29:15
Mustafa bought 1 AAPL for 33.2 USD from Ali on 2024-11-18 at 10:29:15
Emre bought 1 BAC for 39.0 USD from Ali on 2024-11-18 at 10:29:15
Emre bought 15 MRT for 36.6 USD from Ali on 2024-11-18 at 10:29:15
Emre bought 9 MRT for 37.8 USD from Mustafa on 2024-11-18 at 10:30:30
Ali bought 6 BAC for 42.1 USD from Emre on 2024-11-18 at 10:31:15
Ali bought 18 NVDA for 35.2 USD from Mustafa on 2024-11-18 at 10:31:15
Emre bought 6 MSFT for 38.7 USD from Oğuz on 2024-11-18 at 10:31:30
Emre bought 4 MRT for 32.0 USD from Oğuz on 2024-11-18 at 10:31:45
Emre bought 4 MRT for 32.0 USD from Oğuz on 2024-11-18 at 10:31:45
Emre bought 2 MRT for 32.0 USD from Oğuz on 2024-11-18 at 10:31:45
Mustafa bought 7 MSFT for 32.1 USD from Oğuz on 2024-11-18 at 10:32:15
Mustafa bought 3 MSFT for 32.3 USD from Emre on 2024-11-18 at 10:32:15
Mustafa bought 5 MSFT for 32.3 USD from Emre on 2024-11-18 at 10:32:15
Emre bought 10 MRT for 37.6 USD from Oğuz on 2024-11-18 at 10:32:30
Ali bought 2 MSFT for 32.3 USD from Emre on 2024-11-18 at 10:33:15
Ali bought 6 MSFT for 33.4 USD from Oğuz on 2024-11-18 at 10:33:15
Mustafa bought 3 MRT for 37.6 USD from Oğuz on 2024-11-18 at 10:33:15
Mustafa bought 5 MRT for 40.5 USD from Oğuz on 2024-11-18 at 10:33:15
Emre bought 1 MSFT for 33.4 USD from Oğuz on 2024-11-18 at 10:33:30
Emre bought 5 MSFT for 32.8 USD from Mustafa on 2024-11-18 at 10:33:30
Ali bought 11 MSFT for 36.4 USD from Emre on 2024-11-18 at 10:34:15
Mustafa bought 11 MSFT for 36.2 USD from Ali on 2024-11-18 at 10:35:15
Mustafa bought 1 MSFT for 36.4 USD from Emre on 2024-11-18 at 10:35:15
Mustafa bought 4 MSFT for 40.8 USD from Emre on 2024-11-18 at 10:35:15
Emre bought 1 NVDA for 37.3 USD from Mustafa on 2024-11-18 at 10:35:15
Emre bought 2 NVDA for 35.2 USD from Mustafa on 2024-11-18 at 10:35:15
Emre bought 10 NVDA for 33.5 USD from Mustafa on 2024-11-18 at 10:35:45
Ali bought 2 BAC for 34.5 USD from Mustafa on 2024-11-18 at 10:36:15
Oğuz bought 5 BAC for 34.5 USD from Mustafa on 2024-11-18 at 10:36:15
Emre bought 11 BAC for 34.5 USD from Mustafa on 2024-11-18 at 10:36:15
Mustafa bought 5 NVDA for 36.1 USD from Emre on 2024-11-18 at 10:36:30
Mustafa bought 8 NVDA for 30.1 USD from Ali on 2024-11-18 at 10:36:45
Oğuz bought 11 NVDA for 30.1 USD from Ali on 2024-11-18 at 10:36:45
Emre bought 7 NVDA for 37.2 USD from Ali on 2024-11-18 at 10:37:15
Mustafa bought 10 MSFT for 30.1 USD from Ali on 2024-11-18 at 10:37:30
Mustafa bought 11 AAPL for 36.5 USD from Emre on 2024-11-18 at 10:37:45
Ali bought 12 MSFT for 32.8 USD from Mustafa on 2024-11-18 at 10:39:15
Oğuz bought 1 MSFT for 30.1 USD from Ali on 2024-11-18 at 10:39:15
Oğuz bought 7 MSFT for 36.6 USD from Mustafa on 2024-11-18 at 10:39:15
Oğuz bought 2 MRT for 37.8 USD from Mustafa on 2024-11-18 at 10:39:30
Oğuz bought 15 MRT for 36.3 USD from Mustafa on 2024-11-18 at 10:39:30
Mustafa bought 9 BAC for 33.1 USD from Emre on 2024-11-18 at 10:40:15
Mustafa bought 9 MRT for 33.8 USD from Oğuz on 2024-11-18 at 10:40:15
Mustafa bought 8 MRT for 33.8 USD from Oğuz on 2024-11-18 at 10:40:15
Emre bought 11 BAC for 39.0 USD from Ali on 2024-11-18 at 10:40:30
Emre bought 4 BAC for 37.6 USD from Ali on 2024-11-18 at 10:40:30
Oğuz bought 4 MSFT for 36.6 USD from Mustafa on 2024-11-18 at 10:40:45
Oğuz bought 16 MSFT for 34.6 USD from Ali on 2024-11-18 at 10:40:45
Ali bought 2 BAC for 33.1 USD from Emre on 2024-11-18 at 10:40:45
Oğuz bought 2 MRT for 32.0 USD from Emre on 2024-11-18 at 10:41:15
Mustafa bought 1 MRT for 32.0 USD from Emre on 2024-11-18 at 10:41:15
Mustafa bought 6 MRT for 32.0 USD from Emre on 2024-11-18 at 10:41:15
Ali bought 10 MSFT for 30.1 USD from Oğuz on 2024-11-18 at 10:41:45
Emre bought 12 AAPL for 41.2 USD from Mustafa on 2024-11-18 at 10:42:30
Oğuz bought 8 BAC for 42.1 USD from Emre on 2024-11-18 at 10:42:45
Oğuz bought 1 BAC for 43.7 USD from Emre on 2024-11-18 at 10:42:45
